<robot name = "robot">
    <link name="0">
        <inertial>
            <origin xyz="0 0 0.5667842257618008" rpy="0 0 0"/>
            <mass value="1" />
            <inertia ixx="100" ixy="0" ixz="0" iyy="100" iyz="0" izz="100" />
        </inertial>
        <visual>
            <origin xyz="0 0 0.5667842257618008" rpy="0 0 0"/>
            <geometry>
                <box size="0.08824164141304901 0.3538208869594002 0.3778561505078672" />
            </geometry>
            <material name="Cyan">
                <color rgba="0 1.0 1.0 1.0"/>
            </material>
        </visual>
        <collision>
            <origin xyz="0 0 0.5667842257618008" rpy="0 0 0"/>
            <geometry>
                <box size="0.08824164141304901 0.3538208869594002 0.3778561505078672" />
            </geometry>
        </collision>
    </link>
    <joint name="0_5" type="revolute">
       <parent link="0"/>
       <child  link="5"/>
       <origin rpy="0 1 0" xyz="0 -0.1769104434797001 0.5667842257618008" />
     <axis xyz="1 0 0"/>
       <limit effort="0.0" lower="-3.14159" upper="3.14159" velocity="0.0"/>
    </joint>
    <link name="5">
        <inertial>
            <origin xyz="-0.19842035266255018 -0.12210249970010495 0.08152748139639952" rpy="0 0 0"/>
            <mass value="1" />
            <inertia ixx="100" ixy="0" ixz="0" iyy="100" iyz="0" izz="100" />
        </inertial>
        <visual>
            <origin xyz="-0.19842035266255018 -0.12210249970010495 0.08152748139639952" rpy="0 0 0"/>
            <geometry>
                <box size="0.40202081737046214 0.2442049994002099 0.488556175937601" />
            </geometry>
            <material name="Cyan">
                <color rgba="0 1.0 1.0 1.0"/>
            </material>
        </visual>
        <collision>
            <origin xyz="-0.19842035266255018 -0.12210249970010495 0.08152748139639952" rpy="0 0 0"/>
            <geometry>
                <box size="0.40202081737046214 0.2442049994002099 0.488556175937601" />
            </geometry>
        </collision>
    </link>
    <joint name="5_6" type="revolute">
       <parent link="5"/>
       <child  link="6"/>
       <origin rpy="1 0 0" xyz="0 -0.2442049994002099 0" />
     <axis xyz="1 0 0"/>
       <limit effort="0.0" lower="-3.14159" upper="3.14159" velocity="0.0"/>
    </joint>
    <link name="6">
        <inertial>
            <origin xyz="0.04012380585131949 -0.13384312845801416 0.0037505531434965356" rpy="0 0 0"/>
            <mass value="1" />
            <inertia ixx="100" ixy="0" ixz="0" iyy="100" iyz="0" izz="100" />
        </inertial>
        <visual>
            <origin xyz="0.04012380585131949 -0.13384312845801416 0.0037505531434965356" rpy="0 0 0"/>
            <geometry>
                <box size="0.27850908413807274 0.2676862569160283 0.7862578085571724" />
            </geometry>
            <material name="Cyan">
                <color rgba="0 1.0 1.0 1.0"/>
            </material>
        </visual>
        <collision>
            <origin xyz="0.04012380585131949 -0.13384312845801416 0.0037505531434965356" rpy="0 0 0"/>
            <geometry>
                <box size="0.27850908413807274 0.2676862569160283 0.7862578085571724" />
            </geometry>
        </collision>
    </link>
</robot>