<robot name = "robot">
    <link name="0">
        <inertial>
            <origin xyz="0 0 0.5811321316380698" rpy="0 0 0"/>
            <mass value="1" />
            <inertia ixx="100" ixy="0" ixz="0" iyy="100" iyz="0" izz="100" />
        </inertial>
        <visual>
            <origin xyz="0 0 0.5811321316380698" rpy="0 0 0"/>
            <geometry>
                <box size="0.9578273428606328 0.6688746319653971 0.3874214210920465" />
            </geometry>
            <material name="Green">
                <color rgba="0 1.0 0 1.0"/>
            </material>
        </visual>
        <collision>
            <origin xyz="0 0 0.5811321316380698" rpy="0 0 0"/>
            <geometry>
                <box size="0.9578273428606328 0.6688746319653971 0.3874214210920465" />
            </geometry>
        </collision>
    </link>
    <joint name="0_1" type="revolute">
       <parent link="0"/>
       <child  link="1"/>
       <origin rpy="0 0 0" xyz="0 0.33443731598269855 0.5811321316380698" />
     <axis xyz="1 0 0"/>
       <limit effort="0.0" lower="-3.14159" upper="3.14159" velocity="0.0"/>
    </joint>
    <joint name="0_5" type="revolute">
       <parent link="0"/>
       <child  link="5"/>
       <origin rpy="0 0 0" xyz="0 -0.33443731598269855 0.5811321316380698" />
     <axis xyz="1 0 0"/>
       <limit effort="0.0" lower="-3.14159" upper="3.14159" velocity="0.0"/>
    </joint>
    <link name="1">
        <inertial>
            <origin xyz="-0.13320838044573854 0.3041667718551693 0.2990785135379999" rpy="0 0 0"/>
            <mass value="1" />
            <inertia ixx="100" ixy="0" ixz="0" iyy="100" iyz="0" izz="100" />
        </inertial>
        <visual>
            <origin xyz="-0.13320838044573854 0.3041667718551693 0.2990785135379999" rpy="0 0 0"/>
            <geometry>
                <box size="0.6431379065419035 0.6083335437103387 0.8336930115237" />
            </geometry>
            <material name="Cyan">
                <color rgba="0 1.0 1.0 1.0"/>
            </material>
        </visual>
        <collision>
            <origin xyz="-0.13320838044573854 0.3041667718551693 0.2990785135379999" rpy="0 0 0"/>
            <geometry>
                <box size="0.6431379065419035 0.6083335437103387 0.8336930115237" />
            </geometry>
        </collision>
    </link>
    <joint name="1_2" type="revolute">
       <parent link="1"/>
       <child  link="2"/>
       <origin rpy="0 0 0" xyz="0 0.6083335437103387 0" />
     <axis xyz="1 0 0"/>
       <limit effort="0.0" lower="-3.14159" upper="3.14159" velocity="0.0"/>
    </joint>
    <link name="2">
        <inertial>
            <origin xyz="-0.14838907870599552 0.44787022287314315 0.059844781172590525" rpy="0 0 0"/>
            <mass value="1" />
            <inertia ixx="100" ixy="0" ixz="0" iyy="100" iyz="0" izz="100" />
        </inertial>
        <visual>
            <origin xyz="-0.14838907870599552 0.44787022287314315 0.059844781172590525" rpy="0 0 0"/>
            <geometry>
                <box size="0.35760810486048655 0.8957404457462863 0.16584893368094325" />
            </geometry>
            <material name="Cyan">
                <color rgba="0 1.0 1.0 1.0"/>
            </material>
        </visual>
        <collision>
            <origin xyz="-0.14838907870599552 0.44787022287314315 0.059844781172590525" rpy="0 0 0"/>
            <geometry>
                <box size="0.35760810486048655 0.8957404457462863 0.16584893368094325" />
            </geometry>
        </collision>
    </link>
    <link name="5">
        <inertial>
            <origin xyz="-0.29121046816068624 -0.02425835589143342 -0.003856557056917523" rpy="0 0 0"/>
            <mass value="1" />
            <inertia ixx="100" ixy="0" ixz="0" iyy="100" iyz="0" izz="100" />
        </inertial>
        <visual>
            <origin xyz="-0.29121046816068624 -0.02425835589143342 -0.003856557056917523" rpy="0 0 0"/>
            <geometry>
                <box size="0.8493235003747565 0.04851671178286684 0.5330615344859472" />
            </geometry>
            <material name="Cyan">
                <color rgba="0 1.0 1.0 1.0"/>
            </material>
        </visual>
        <collision>
            <origin xyz="-0.29121046816068624 -0.02425835589143342 -0.003856557056917523" rpy="0 0 0"/>
            <geometry>
                <box size="0.8493235003747565 0.04851671178286684 0.5330615344859472" />
            </geometry>
        </collision>
    </link>
</robot>