<robot name = "robot">
    <link name="0">
        <inertial>
            <origin xyz="0 0 1.4195966853406532" rpy="0 0 0"/>
            <mass value="1" />
            <inertia ixx="100" ixy="0" ixz="0" iyy="100" iyz="0" izz="100" />
        </inertial>
        <visual>
            <origin xyz="0 0 1.4195966853406532" rpy="0 0 0"/>
            <geometry>
                <box size="0.045244201902604086 0.11823610838555829 0.9463977902271021" />
            </geometry>
            <material name="Green">
                <color rgba="0 1.0 0 1.0"/>
            </material>
        </visual>
        <collision>
            <origin xyz="0 0 1.4195966853406532" rpy="0 0 0"/>
            <geometry>
                <box size="0.045244201902604086 0.11823610838555829 0.9463977902271021" />
            </geometry>
        </collision>
    </link>
    <joint name="0_1" type="revolute">
       <parent link="0"/>
       <child  link="1"/>
       <origin rpy="0 0 0" xyz="0 0.05911805419277914 1.4195966853406532" />
     <axis xyz="1 0 0"/>
       <limit effort="0.0" lower="-3.14159" upper="3.14159" velocity="0.0"/>
    </joint>
    <joint name="0_5" type="revolute">
       <parent link="0"/>
       <child  link="5"/>
       <origin rpy="0 1 0" xyz="0 -0.05911805419277914 1.4195966853406532" />
     <axis xyz="1 0 0"/>
       <limit effort="0.0" lower="-3.14159" upper="3.14159" velocity="0.0"/>
    </joint>
    <joint name="0_10" type="revolute">
       <parent link="0"/>
       <child  link="10"/>
       <origin rpy="1 0 0" xyz="0 0.05911805419277914 1.8927955804542043" />
     <axis xyz="1 0 0"/>
       <limit effort="0.0" lower="-3.14159" upper="3.14159" velocity="0.0"/>
    </joint>
    <link name="1">
        <inertial>
            <origin xyz="-0.29282343218474066 0.0938638257752336 0.20229869427926717" rpy="0 0 0"/>
            <mass value="1" />
            <inertia ixx="100" ixy="0" ixz="0" iyy="100" iyz="0" izz="100" />
        </inertial>
        <visual>
            <origin xyz="-0.29282343218474066 0.0938638257752336 0.20229869427926717" rpy="0 0 0"/>
            <geometry>
                <box size="0.8124343860358039 0.1877276515504672 0.7765725121717121" />
            </geometry>
            <material name="Green">
                <color rgba="0 1.0 0 1.0"/>
            </material>
        </visual>
        <collision>
            <origin xyz="-0.29282343218474066 0.0938638257752336 0.20229869427926717" rpy="0 0 0"/>
            <geometry>
                <box size="0.8124343860358039 0.1877276515504672 0.7765725121717121" />
            </geometry>
        </collision>
    </link>
    <joint name="1_2" type="revolute">
       <parent link="1"/>
       <child  link="2"/>
       <origin rpy="1 0 0" xyz="0 0.1877276515504672 0" />
     <axis xyz="1 0 0"/>
       <limit effort="0.0" lower="-3.14159" upper="3.14159" velocity="0.0"/>
    </joint>
    <link name="2">
        <inertial>
            <origin xyz="0.025399174425231652 0.0528631663444663 0.010353608183693836" rpy="0 0 0"/>
            <mass value="1" />
            <inertia ixx="100" ixy="0" ixz="0" iyy="100" iyz="0" izz="100" />
        </inertial>
        <visual>
            <origin xyz="0.025399174425231652 0.0528631663444663 0.010353608183693836" rpy="0 0 0"/>
            <geometry>
                <box size="0.33292002382034197 0.1057263326889326 0.2553146848741064" />
            </geometry>
            <material name="Green">
                <color rgba="0 1.0 0 1.0"/>
            </material>
        </visual>
        <collision>
            <origin xyz="0.025399174425231652 0.0528631663444663 0.010353608183693836" rpy="0 0 0"/>
            <geometry>
                <box size="0.33292002382034197 0.1057263326889326 0.2553146848741064" />
            </geometry>
        </collision>
    </link>
    <link name="5">
        <inertial>
            <origin xyz="-0.17744920071138015 -0.2138961214403803 -0.05133923941713968" rpy="0 0 0"/>
            <mass value="1" />
            <inertia ixx="100" ixy="0" ixz="0" iyy="100" iyz="0" izz="100" />
        </inertial>
        <visual>
            <origin xyz="-0.17744920071138015 -0.2138961214403803 -0.05133923941713968" rpy="0 0 0"/>
            <geometry>
                <box size="0.4140356765438694 0.4277922428807606 0.40078095658659885" />
            </geometry>
            <material name="Green">
                <color rgba="0 1.0 0 1.0"/>
            </material>
        </visual>
        <collision>
            <origin xyz="-0.17744920071138015 -0.2138961214403803 -0.05133923941713968" rpy="0 0 0"/>
            <geometry>
                <box size="0.4140356765438694 0.4277922428807606 0.40078095658659885" />
            </geometry>
        </collision>
    </link>
    <joint name="5_6" type="revolute">
       <parent link="5"/>
       <child  link="6"/>
       <origin rpy="1 0 0" xyz="0 -0.4277922428807606 0" />
     <axis xyz="1 0 0"/>
       <limit effort="0.0" lower="-3.14159" upper="3.14159" velocity="0.0"/>
    </joint>
    <link name="6">
        <inertial>
            <origin xyz="0.21189634530902796 -0.32131543284811565 -0.02358342039545054" rpy="0 0 0"/>
            <mass value="1" />
            <inertia ixx="100" ixy="0" ixz="0" iyy="100" iyz="0" izz="100" />
        </inertial>
        <visual>
            <origin xyz="0.21189634530902796 -0.32131543284811565 -0.02358342039545054" rpy="0 0 0"/>
            <geometry>
                <box size="0.7886590159628379 0.6426308656962313 0.786262419880354" />
            </geometry>
            <material name="Cyan">
                <color rgba="0 1.0 1.0 1.0"/>
            </material>
        </visual>
        <collision>
            <origin xyz="0.21189634530902796 -0.32131543284811565 -0.02358342039545054" rpy="0 0 0"/>
            <geometry>
                <box size="0.7886590159628379 0.6426308656962313 0.786262419880354" />
            </geometry>
        </collision>
    </link>
    <link name="10">
        <inertial>
            <origin xyz="-0.03274748059322198 0.24618346181332235 0.07005790443081947" rpy="0 0 0"/>
            <mass value="1" />
            <inertia ixx="100" ixy="0" ixz="0" iyy="100" iyz="0" izz="100" />
        </inertial>
        <visual>
            <origin xyz="-0.03274748059322198 0.24618346181332235 0.07005790443081947" rpy="0 0 0"/>
            <geometry>
                <box size="0.15111612961758117 0.594526133520221 0.14011580886163894" />
            </geometry>
            <material name="Green">
                <color rgba="0 1.0 0 1.0"/>
            </material>
        </visual>
        <collision>
            <origin xyz="-0.03274748059322198 0.24618346181332235 0.07005790443081947" rpy="0 0 0"/>
            <geometry>
                <box size="0.15111612961758117 0.594526133520221 0.14011580886163894" />
            </geometry>
        </collision>
    </link>
    <joint name="10_11" type="revolute">
       <parent link="10"/>
       <child  link="11"/>
       <origin rpy="0 1 0" xyz="0 0 0.14011580886163894" />
     <axis xyz="1 1 0"/>
       <limit effort="0.0" lower="-3.14159" upper="3.14159" velocity="0.0"/>
    </joint>
    <link name="11">
        <inertial>
            <origin xyz="0.06714751583882275 0.1515750885523657 0.15675423642479536" rpy="0 0 0"/>
            <mass value="1" />
            <inertia ixx="100" ixy="0" ixz="0" iyy="100" iyz="0" izz="100" />
        </inertial>
        <visual>
            <origin xyz="0.06714751583882275 0.1515750885523657 0.15675423642479536" rpy="0 0 0"/>
            <geometry>
                <box size="0.5517371411791088 0.5681933848472894 0.3135084728495907" />
            </geometry>
            <material name="Cyan">
                <color rgba="0 1.0 1.0 1.0"/>
            </material>
        </visual>
        <collision>
            <origin xyz="0.06714751583882275 0.1515750885523657 0.15675423642479536" rpy="0 0 0"/>
            <geometry>
                <box size="0.5517371411791088 0.5681933848472894 0.3135084728495907" />
            </geometry>
        </collision>
    </link>
</robot>