<robot name = "robot">
    <link name="0">
        <inertial>
            <origin xyz="0 0 0.8052894547159716" rpy="0 0 0"/>
            <mass value="1" />
            <inertia ixx="100" ixy="0" ixz="0" iyy="100" iyz="0" izz="100" />
        </inertial>
        <visual>
            <origin xyz="0 0 0.8052894547159716" rpy="0 0 0"/>
            <geometry>
                <box size="0.2957629124207677 0.45511651060475533 0.5368596364773144" />
            </geometry>
            <material name="Green">
                <color rgba="0 1.0 0 1.0"/>
            </material>
        </visual>
        <collision>
            <origin xyz="0 0 0.8052894547159716" rpy="0 0 0"/>
            <geometry>
                <box size="0.2957629124207677 0.45511651060475533 0.5368596364773144" />
            </geometry>
        </collision>
    </link>
    <joint name="0_1" type="revolute">
       <parent link="0"/>
       <child  link="1"/>
       <origin rpy="0 0 0" xyz="0 0.22755825530237767 0.8052894547159716" />
     <axis xyz="1 0 0"/>
       <limit effort="0.0" lower="-3.14159" upper="3.14159" velocity="0.0"/>
    </joint>
    <joint name="0_5" type="revolute">
       <parent link="0"/>
       <child  link="5"/>
       <origin rpy="0 0 0" xyz="0 -0.22755825530237767 0.8052894547159716" />
     <axis xyz="1 0 0"/>
       <limit effort="0.0" lower="-3.14159" upper="3.14159" velocity="0.0"/>
    </joint>
    <joint name="0_10" type="revolute">
       <parent link="0"/>
       <child  link="10"/>
       <origin rpy="0 0 0" xyz="0 0.22755825530237767 1.0737192729546288" />
     <axis xyz="1 0 0"/>
       <limit effort="0.0" lower="-3.14159" upper="3.14159" velocity="0.0"/>
    </joint>
    <link name="1">
        <inertial>
            <origin xyz="0.3170803742077934 0.3281472419729526 -0.019662734517230565" rpy="0 0 0"/>
            <mass value="1" />
            <inertia ixx="100" ixy="0" ixz="0" iyy="100" iyz="0" izz="100" />
        </inertial>
        <visual>
            <origin xyz="0.3170803742077934 0.3281472419729526 -0.019662734517230565" rpy="0 0 0"/>
            <geometry>
                <box size="0.8456650054580982 0.6562944839459052 0.8249984779515052" />
            </geometry>
            <material name="Cyan">
                <color rgba="0 1.0 1.0 1.0"/>
            </material>
        </visual>
        <collision>
            <origin xyz="0.3170803742077934 0.3281472419729526 -0.019662734517230565" rpy="0 0 0"/>
            <geometry>
                <box size="0.8456650054580982 0.6562944839459052 0.8249984779515052" />
            </geometry>
        </collision>
    </link>
    <joint name="1_2" type="revolute">
       <parent link="1"/>
       <child  link="2"/>
       <origin rpy="1 0 0" xyz="0 0.6562944839459052 0" />
     <axis xyz="1 0 0"/>
       <limit effort="0.0" lower="-3.14159" upper="3.14159" velocity="0.0"/>
    </joint>
    <link name="2">
        <inertial>
            <origin xyz="0.22933421099536055 0.17898080019228746 -0.20228567890920643" rpy="0 0 0"/>
            <mass value="1" />
            <inertia ixx="100" ixy="0" ixz="0" iyy="100" iyz="0" izz="100" />
        </inertial>
        <visual>
            <origin xyz="0.22933421099536055 0.17898080019228746 -0.20228567890920643" rpy="0 0 0"/>
            <geometry>
                <box size="0.7657388841763955 0.3579616003845749 0.43626576600667455" />
            </geometry>
            <material name="Green">
                <color rgba="0 1.0 0 1.0"/>
            </material>
        </visual>
        <collision>
            <origin xyz="0.22933421099536055 0.17898080019228746 -0.20228567890920643" rpy="0 0 0"/>
            <geometry>
                <box size="0.7657388841763955 0.3579616003845749 0.43626576600667455" />
            </geometry>
        </collision>
    </link>
    <joint name="2_3" type="revolute">
       <parent link="2"/>
       <child  link="3"/>
       <origin rpy="1 0 0" xyz="0 0.3579616003845749 0" />
     <axis xyz="1 0 0"/>
       <limit effort="0.0" lower="-3.14159" upper="3.14159" velocity="0.0"/>
    </joint>
    <link name="3">
        <inertial>
            <origin xyz="0.2684247601034123 0.22013911663918115 -0.13442769496538562" rpy="0 0 0"/>
            <mass value="1" />
            <inertia ixx="100" ixy="0" ixz="0" iyy="100" iyz="0" izz="100" />
        </inertial>
        <visual>
            <origin xyz="0.2684247601034123 0.22013911663918115 -0.13442769496538562" rpy="0 0 0"/>
            <geometry>
                <box size="0.6516391291242368 0.4402782332783623 0.28943335249112867" />
            </geometry>
            <material name="Green">
                <color rgba="0 1.0 0 1.0"/>
            </material>
        </visual>
        <collision>
            <origin xyz="0.2684247601034123 0.22013911663918115 -0.13442769496538562" rpy="0 0 0"/>
            <geometry>
                <box size="0.6516391291242368 0.4402782332783623 0.28943335249112867" />
            </geometry>
        </collision>
    </link>
    <link name="5">
        <inertial>
            <origin xyz="0.006289550561645879 -0.041366082142277195 0.014054999825165579" rpy="0 0 0"/>
            <mass value="1" />
            <inertia ixx="100" ixy="0" ixz="0" iyy="100" iyz="0" izz="100" />
        </inertial>
        <visual>
            <origin xyz="0.006289550561645879 -0.041366082142277195 0.014054999825165579" rpy="0 0 0"/>
            <geometry>
                <box size="0.013015575586062046 0.08273216428455439 0.16576933692134307" />
            </geometry>
            <material name="Cyan">
                <color rgba="0 1.0 1.0 1.0"/>
            </material>
        </visual>
        <collision>
            <origin xyz="0.006289550561645879 -0.041366082142277195 0.014054999825165579" rpy="0 0 0"/>
            <geometry>
                <box size="0.013015575586062046 0.08273216428455439 0.16576933692134307" />
            </geometry>
        </collision>
    </link>
    <link name="10">
        <inertial>
            <origin xyz="-0.07493307911149484 -0.08049816654437977 0.03611280970196264" rpy="0 0 0"/>
            <mass value="1" />
            <inertia ixx="100" ixy="0" ixz="0" iyy="100" iyz="0" izz="100" />
        </inertial>
        <visual>
            <origin xyz="-0.07493307911149484 -0.08049816654437977 0.03611280970196264" rpy="0 0 0"/>
            <geometry>
                <box size="0.6532870243885698 0.5115006109227194 0.07222561940392529" />
            </geometry>
            <material name="Cyan">
                <color rgba="0 1.0 1.0 1.0"/>
            </material>
        </visual>
        <collision>
            <origin xyz="-0.07493307911149484 -0.08049816654437977 0.03611280970196264" rpy="0 0 0"/>
            <geometry>
                <box size="0.6532870243885698 0.5115006109227194 0.07222561940392529" />
            </geometry>
        </collision>
    </link>
    <joint name="10_11" type="revolute">
       <parent link="10"/>
       <child  link="11"/>
       <origin rpy="0 1 0" xyz="0 0 0.07222561940392529" />
     <axis xyz="1 1 0"/>
       <limit effort="0.0" lower="-3.14159" upper="3.14159" velocity="0.0"/>
    </joint>
    <link name="11">
        <inertial>
            <origin xyz="0.2161711091155201 -0.005867624484349144 0.151787874561967" rpy="0 0 0"/>
            <mass value="1" />
            <inertia ixx="100" ixy="0" ixz="0" iyy="100" iyz="0" izz="100" />
        </inertial>
        <visual>
            <origin xyz="0.2161711091155201 -0.005867624484349144 0.151787874561967" rpy="0 0 0"/>
            <geometry>
                <box size="0.732428298691565 0.10582802108657864 0.303575749123934" />
            </geometry>
            <material name="Cyan">
                <color rgba="0 1.0 1.0 1.0"/>
            </material>
        </visual>
        <collision>
            <origin xyz="0.2161711091155201 -0.005867624484349144 0.151787874561967" rpy="0 0 0"/>
            <geometry>
                <box size="0.732428298691565 0.10582802108657864 0.303575749123934" />
            </geometry>
        </collision>
    </link>
</robot>