<robot name = "robot">
    <link name="Torso">
        <inertial>
            <origin xyz="0 0 1" rpy="0 0 0"/>
            <mass value="1" />
            <inertia ixx="100" ixy="0" ixz="0" iyy="100" iyz="0" izz="100" />
        </inertial>
        <visual>
            <origin xyz="0 0 1" rpy="0 0 0"/>
            <geometry>
                <box size="1 3 1" />
            </geometry>
            <material name="Cyan">
                <color rgba="0 1.0 1.0 1.0"/>
            </material>
        </visual>
        <collision>
            <origin xyz="0 0 1" rpy="0 0 0"/>
            <geometry>
                <box size="1 3 1" />
            </geometry>
        </collision>
    </link>
    <joint name="Torso_RightLeg1" type="revolute">
       <parent link="Torso"/>
       <child  link="RightLeg1"/>
       <origin rpy="0 0 0" xyz="0.5 0 1" />
     <axis xyz="0 0 1"/>
       <limit effort="0.0" lower="-3.14159" upper="3.14159" velocity="0.0"/>
    </joint>
    <link name="RightLeg1">
        <inertial>
            <origin xyz="0.5 0 0" rpy="0 0 0"/>
            <mass value="1" />
            <inertia ixx="100" ixy="0" ixz="0" iyy="100" iyz="0" izz="100" />
        </inertial>
        <visual>
            <origin xyz="0.5 0 0" rpy="0 0 0"/>
            <geometry>
                <box size="1 0.2 0.2" />
            </geometry>
            <material name="Cyan">
                <color rgba="0 1.0 1.0 1.0"/>
            </material>
        </visual>
        <collision>
            <origin xyz="0.5 0 0" rpy="0 0 0"/>
            <geometry>
                <box size="1 0.2 0.2" />
            </geometry>
        </collision>
    </link>
    <joint name="RightLeg_RightLowerLeg1" type="revolute">
       <parent link="RightLeg1"/>
       <child  link="RightLowerLeg1"/>
       <origin rpy="0 0 0" xyz="1 0 0" />
     <axis xyz="0 0 1"/>
       <limit effort="0.0" lower="-3.14159" upper="3.14159" velocity="0.0"/>
    </joint>
    <link name="RightLowerLeg1">
        <inertial>
            <origin xyz="0 0 -0.5" rpy="0 0 0"/>
            <mass value="1" />
            <inertia ixx="100" ixy="0" ixz="0" iyy="100" iyz="0" izz="100" />
        </inertial>
        <visual>
            <origin xyz="0 0 -0.5" rpy="0 0 0"/>
            <geometry>
                <box size="0.2 0.2 1" />
            </geometry>
            <material name="Cyan">
                <color rgba="0 1.0 1.0 1.0"/>
            </material>
        </visual>
        <collision>
            <origin xyz="0 0 -0.5" rpy="0 0 0"/>
            <geometry>
                <box size="0.2 0.2 1" />
            </geometry>
        </collision>
    </link>
    <joint name="Torso_RightLeg2" type="revolute">
       <parent link="Torso"/>
       <child  link="RightLeg2"/>
       <origin rpy="0 0 0" xyz="0.5 1 1" />
     <axis xyz="0 0 1"/>
       <limit effort="0.0" lower="-3.14159" upper="3.14159" velocity="0.0"/>
    </joint>
    <link name="RightLeg2">
        <inertial>
            <origin xyz="0.5 0 0" rpy="0 0 0"/>
            <mass value="1" />
            <inertia ixx="100" ixy="0" ixz="0" iyy="100" iyz="0" izz="100" />
        </inertial>
        <visual>
            <origin xyz="0.5 0 0" rpy="0 0 0"/>
            <geometry>
                <box size="1 0.2 0.2" />
            </geometry>
            <material name="Cyan">
                <color rgba="0 1.0 1.0 1.0"/>
            </material>
        </visual>
        <collision>
            <origin xyz="0.5 0 0" rpy="0 0 0"/>
            <geometry>
                <box size="1 0.2 0.2" />
            </geometry>
        </collision>
    </link>
    <joint name="RightLeg_RightLowerLeg2" type="revolute">
       <parent link="RightLeg2"/>
       <child  link="RightLowerLeg2"/>
       <origin rpy="0 0 0" xyz="1 0 0" />
     <axis xyz="0 0 1"/>
       <limit effort="0.0" lower="-3.14159" upper="3.14159" velocity="0.0"/>
    </joint>
    <link name="RightLowerLeg2">
        <inertial>
            <origin xyz="0 0 -0.5" rpy="0 0 0"/>
            <mass value="1" />
            <inertia ixx="100" ixy="0" ixz="0" iyy="100" iyz="0" izz="100" />
        </inertial>
        <visual>
            <origin xyz="0 0 -0.5" rpy="0 0 0"/>
            <geometry>
                <box size="0.2 0.2 1" />
            </geometry>
            <material name="Cyan">
                <color rgba="0 1.0 1.0 1.0"/>
            </material>
        </visual>
        <collision>
            <origin xyz="0 0 -0.5" rpy="0 0 0"/>
            <geometry>
                <box size="0.2 0.2 1" />
            </geometry>
        </collision>
    </link>
    <joint name="Torso_LeftLeg1" type="revolute">
       <parent link="Torso"/>
       <child  link="LeftLeg1"/>
       <origin rpy="0 0 0" xyz="-0.5 0 1" />
     <axis xyz="0 0 1"/>
       <limit effort="0.0" lower="-3.14159" upper="3.14159" velocity="0.0"/>
    </joint>
    <link name="LeftLeg1">
        <inertial>
            <origin xyz="-0.5 0 0" rpy="0 0 0"/>
            <mass value="1" />
            <inertia ixx="100" ixy="0" ixz="0" iyy="100" iyz="0" izz="100" />
        </inertial>
        <visual>
            <origin xyz="-0.5 0 0" rpy="0 0 0"/>
            <geometry>
                <box size="1 0.2 0.2" />
            </geometry>
            <material name="Cyan">
                <color rgba="0 1.0 1.0 1.0"/>
            </material>
        </visual>
        <collision>
            <origin xyz="-0.5 0 0" rpy="0 0 0"/>
            <geometry>
                <box size="1 0.2 0.2" />
            </geometry>
        </collision>
    </link>
    <joint name="LeftLeg_LeftLowerLeg1" type="revolute">
       <parent link="LeftLeg1"/>
       <child  link="LeftLowerLeg1"/>
       <origin rpy="0 0 0" xyz="-1 0 0" />
     <axis xyz="0 0 1"/>
       <limit effort="0.0" lower="-3.14159" upper="3.14159" velocity="0.0"/>
    </joint>
    <link name="LeftLowerLeg1">
        <inertial>
            <origin xyz="0 0 -0.5" rpy="0 0 0"/>
            <mass value="1" />
            <inertia ixx="100" ixy="0" ixz="0" iyy="100" iyz="0" izz="100" />
        </inertial>
        <visual>
            <origin xyz="0 0 -0.5" rpy="0 0 0"/>
            <geometry>
                <box size="0.2 0.2 1" />
            </geometry>
            <material name="Cyan">
                <color rgba="0 1.0 1.0 1.0"/>
            </material>
        </visual>
        <collision>
            <origin xyz="0 0 -0.5" rpy="0 0 0"/>
            <geometry>
                <box size="0.2 0.2 1" />
            </geometry>
        </collision>
    </link>
    <joint name="Torso_LeftLeg2" type="revolute">
       <parent link="Torso"/>
       <child  link="LeftLeg2"/>
       <origin rpy="0 0 0" xyz="-0.5 1 1" />
     <axis xyz="0 0 1"/>
       <limit effort="0.0" lower="-3.14159" upper="3.14159" velocity="0.0"/>
    </joint>
    <link name="LeftLeg2">
        <inertial>
            <origin xyz="-0.5 0 0" rpy="0 0 0"/>
            <mass value="1" />
            <inertia ixx="100" ixy="0" ixz="0" iyy="100" iyz="0" izz="100" />
        </inertial>
        <visual>
            <origin xyz="-0.5 0 0" rpy="0 0 0"/>
            <geometry>
                <box size="1 0.2 0.2" />
            </geometry>
            <material name="Cyan">
                <color rgba="0 1.0 1.0 1.0"/>
            </material>
        </visual>
        <collision>
            <origin xyz="-0.5 0 0" rpy="0 0 0"/>
            <geometry>
                <box size="1 0.2 0.2" />
            </geometry>
        </collision>
    </link>
    <joint name="LeftLeg_LeftLowerLeg2" type="revolute">
       <parent link="LeftLeg2"/>
       <child  link="LeftLowerLeg2"/>
       <origin rpy="0 0 0" xyz="-1 0 0" />
     <axis xyz="0 0 1"/>
       <limit effort="0.0" lower="-3.14159" upper="3.14159" velocity="0.0"/>
    </joint>
    <link name="LeftLowerLeg2">
        <inertial>
            <origin xyz="0 0 -0.5" rpy="0 0 0"/>
            <mass value="1" />
            <inertia ixx="100" ixy="0" ixz="0" iyy="100" iyz="0" izz="100" />
        </inertial>
        <visual>
            <origin xyz="0 0 -0.5" rpy="0 0 0"/>
            <geometry>
                <box size="0.2 0.2 1" />
            </geometry>
            <material name="Cyan">
                <color rgba="0 1.0 1.0 1.0"/>
            </material>
        </visual>
        <collision>
            <origin xyz="0 0 -0.5" rpy="0 0 0"/>
            <geometry>
                <box size="0.2 0.2 1" />
            </geometry>
        </collision>
    </link>
</robot>